Workbook

Sheet Materialliste
A1: SAP | B1: Bezeichnung | C1: Lagerstand | D1: Meldebestand | E1: StkProKarton | F1: StkProPalette
A2: 40290012 | B2: Schraube M8x40 Typ A | C2: 480 | D2: 480 | E2: 24 | F2: 480
A3: 40229779 | B3: Mutter M8 Typ A | C3: 480 | D3: 240 | E3: 12 | F3: 240
A4: 40211614 | B4: Unterlegscheibe 8,4 Typ A | C4: 1440 | D4: 1440 | E4: 24 | F4: 1440
A5: 40214943 | B5: Kabelbinder 200mm Typ A | C5: 3000 | D5: 3000 | E5: 50 | F5: 3000
A6: 40383028 | B6: Folie 500mm Typ A | C6: 8000 | D6: 2000 | E6: 100 | F6: 2000
A7: 40381812 | B7: Karton 600x400 Typ A | C7: 90 | D7: 30 | E7: 0 | F7: 30
A8: 40287867 | B8: Klebeband braun Typ A | C8: 3000 | D8: 1000 | E8: 50 | F8: 1000
A9: 40970777 | B9: Etikett 100x50 Typ A | C9: 240 | D9: 120 | E9: 6 | F9: 120
A10: 40227101 | B10: Dichtung DN50 Typ A | C10: 1000 | D10: 1000 | E10: 50 | F10: 1000
A11: 40734374 | B11: Rohr 1/2 Zoll Typ A | C11: 18000 | D11: 6000 | E11: 100 | F11: 6000
A12: 40848628 | B12: Winkel 90 Grad Typ A | C12: 2880 | D12: 960 | E12: 24 | F12: 960
A13: 40335070 | B13: Scharnier 60mm Typ A | C13: 3000 | D13: 3000 | E13: 100 | F13: 3000
... A51: 40710530 | B51: Rohr 1/2 Zoll Typ C | C51: 4000 | D51: 1000 | E51: 50 | F51: 1000

Sheet Stellplaetze
A1: Stellplatz | B1: SAP
A2: 1
A3: 2
A4: 3
A5: 4 | B5: 40498927
A6: 5 | B6: 40560777
A7: 6 | B7: 40362103
A8: 7
A9: 8 | B9: 40775919
A10: 9
A11: 10
A12: 11
A13: 12
A14: 13
A15: 14
A16: 15
A17: 16 | B17: 40393478
A18: 17
A19: 18
A20: 19
A21: 20
A22: 21
A23: 22 | B23: 40734374
A24: 23 | B24: 40866571
A25: 24
A26: 25
A27: 26
A28: 27 | B28: 40362103
A29: 28
A30: 29
A31: 30
A32: 31 | B32: 40734374
A33: 32
A34: 33 | B34: 40951642
A35: 34 | B35: 40436613
A36: 35
A37: 36 | B37: 40404197
A38: 37
A39: 38 | B39: 40362103
A40: 39 | B40: 40442533
...

Sheet Protokoll
A1: Zeit | B1: Stellplatz | C1: SAP | D1: Aktion | E1: Einheit | F1: Anzahl | G1: Stueck | H1: NeuerBestand

Sheet Lageruebersicht
A1: Stellplatz | B1: SAP | C1: Bezeichnung | D1: Lagerstand (alle Plaetze) | E1: Meldebestand | F1: Unter Meldebestand?
A2: =IFERROR(INDEX(tblStellplatz[Stellplatz],ROW()-1),"") | B2: =IFERROR(INDEX(tblStellplatz[SAP],ROW()-1),"") | C2: =IF(B2="","",IFERROR(INDEX(tblMaterial[Bezeichnung],MATCH(B2,tblMaterial[SAP],0)),"?")) | D2: =IF(B2="","",IFERROR(INDEX(tblMaterial[Lagerstand],MATCH(B2,tblMaterial[SAP],0)),"?")) | E2: =IF(B2="","",IFERROR(INDEX(tblMaterial[Meldebestand],MATCH(B2,tblMaterial[SAP],0)),"?")) | F2: =IF(OR(B2="",NOT(ISNUMBER(D2))),"",IF(D2<E2,"JA",""))
A3: =IFERROR(INDEX(tblStellplatz[Stellplatz],ROW()-1),"") | B3: =IFERROR(INDEX(tblStellplatz[SAP],ROW()-1),"") | C3: =IF(B3="","",IFERROR(INDEX(tblMaterial[Bezeichnung],MATCH(B3,tblMaterial[SAP],0)),"?")) | D3: =IF(B3="","",IFERROR(INDEX(tblMaterial[Lagerstand],MATCH(B3,tblMaterial[SAP],0)),"?")) | E3: =IF(B3="","",IFERROR(INDEX(tblMaterial[Meldebestand],MATCH(B3,tblMaterial[SAP],0)),"?")) | F3: =IF(OR(B3="",NOT(ISNUMBER(D3))),"",IF(D3<E3,"JA",""))
A4: =IFERROR(INDEX(tblStellplatz[Stellplatz],ROW()-1),"") | B4: =IFERROR(INDEX(tblStellplatz[SAP],ROW()-1),"") | C4: =IF(B4="","",IFERROR(INDEX(tblMaterial[Bezeichnung],MATCH(B4,tblMaterial[SAP],0)),"?")) | D4: =IF(B4="","",IFERROR(INDEX(tblMaterial[Lagerstand],MATCH(B4,tblMaterial[SAP],0)),"?")) | E4: =IF(B4="","",IFERROR(INDEX(tblMaterial[Meldebestand],MATCH(B4,tblMaterial[SAP],0)),"?")) | F4: =IF(OR(B4="",NOT(ISNUMBER(D4))),"",IF(D4<E4,"JA",""))
A5: =IFERROR(INDEX(tblStellplatz[Stellplatz],ROW()-1),"") | B5: =IFERROR(INDEX(tblStellplatz[SAP],ROW()-1),"") | C5: =IF(B5="","",IFERROR(INDEX(tblMaterial[Bezeichnung],MATCH(B5,tblMaterial[SAP],0)),"?")) | D5: =IF(B5="","",IFERROR(INDEX(tblMaterial[Lagerstand],MATCH(B5,tblMaterial[SAP],0)),"?")) | E5: =IF(B5="","",IFERROR(INDEX(tblMaterial[Meldebestand],MATCH(B5,tblMaterial[SAP],0)),"?")) | F5: =IF(OR(B5="",NOT(ISNUMBER(D5))),"",IF(D5<E5,"JA",""))
A6: =IFERROR(INDEX(tblStellplatz[Stellplatz],ROW()-1),"") | B6: =IFERROR(INDEX(tblStellplatz[SAP],ROW()-1),"") | C6: =IF(B6="","",IFERROR(INDEX(tblMaterial[Bezeichnung],MATCH(B6,tblMaterial[SAP],0)),"?")) | D6: =IF(B6="","",IFERROR(INDEX(tblMaterial[Lagerstand],MATCH(B6,tblMaterial[SAP],0)),"?")) | E6: =IF(B6="","",IFERROR(INDEX(tblMaterial[Meldebestand],MATCH(B6,tblMaterial[SAP],0)),"?")) | F6: =IF(OR(B6="",NOT(ISNUMBER(D6))),"",IF(D6<E6,"JA",""))
A7: =IFERROR(INDEX(tblStellplatz[Stellplatz],ROW()-1),"") | B7: =IFERROR(INDEX(tblStellplatz[SAP],ROW()-1),"") | C7: =IF(B7="","",IFERROR(INDEX(tblMaterial[Bezeichnung],MATCH(B7,tblMaterial[SAP],0)),"?")) | D7: =IF(B7="","",IFERROR(INDEX(tblMaterial[Lagerstand],MATCH(B7,tblMaterial[SAP],0)),"?")) | E7: =IF(B7="","",IFERROR(INDEX(tblMaterial[Meldebestand],MATCH(B7,tblMaterial[SAP],0)),"?")) | F7: =IF(OR(B7="",NOT(ISNUMBER(D7))),"",IF(D7<E7,"JA",""))
A8: =IFERROR(INDEX(tblStellplatz[Stellplatz],ROW()-1),"") | B8: =IFERROR(INDEX(tblStellplatz[SAP],ROW()-1),"") | C8: =IF(B8="","",IFERROR(INDEX(tblMaterial[Bezeichnung],MATCH(B8,tblMaterial[SAP],0)),"?")) | D8: =IF(B8="","",IFERROR(INDEX(tblMaterial[Lagerstand],MATCH(B8,tblMaterial[SAP],0)),"?")) | E8: =IF(B8="","",IFERROR(INDEX(tblMaterial[Meldebestand],MATCH(B8,tblMaterial[SAP],0)),"?")) | F8: =IF(OR(B8="",NOT(ISNUMBER(D8))),"",IF(D8<E8,"JA",""))
A9: =IFERROR(INDEX(tblStellplatz[Stellplatz],ROW()-1),"") | B9: =IFERROR(INDEX(tblStellplatz[SAP],ROW()-1),"") | C9: =IF(B9="","",IFERROR(INDEX(tblMaterial[Bezeichnung],MATCH(B9,tblMaterial[SAP],0)),"?")) | D9: =IF(B9="","",IFERROR(INDEX(tblMaterial[Lagerstand],MATCH(B9,tblMaterial[SAP],0)),"?")) | E9: =IF(B9="","",IFERROR(INDEX(tblMaterial[Meldebestand],MATCH(B9,tblMaterial[SAP],0)),"?")) | F9: =IF(OR(B9="",NOT(ISNUMBER(D9))),"",IF(D9<E9,"JA",""))
A10: =IFERROR(INDEX(tblStellplatz[Stellplatz],ROW()-1),"") | B10: =IFERROR(INDEX(tblStellplatz[SAP],ROW()-1),"") | C10: =IF(B10="","",IFERROR(INDEX(tblMaterial[Bezeichnung],MATCH(B10,tblMaterial[SAP],0)),"?")) | D10: =IF(B10="","",IFERROR(INDEX(tblMaterial[Lagerstand],MATCH(B10,tblMaterial[SAP],0)),"?")) | E10: =IF(B10="","",IFERROR(INDEX(tblMaterial[Meldebestand],MATCH(B10,tblMaterial[SAP],0)),"?")) | F10: =IF(OR(B10="",NOT(ISNUMBER(D10))),"",IF(D10<E10,"JA",""))
A11: =IFERROR(INDEX(tblStellplatz[Stellplatz],ROW()-1),"") | B11: =IFERROR(INDEX(tblStellplatz[SAP],ROW()-1),"") | C11: =IF(B11="","",IFERROR(INDEX(tblMaterial[Bezeichnung],MATCH(B11,tblMaterial[SAP],0)),"?")) | D11: =IF(B11="","",IFERROR(INDEX(tblMaterial[Lagerstand],MATCH(B11,tblMaterial[SAP],0)),"?")) | E11: =IF(B11="","",IFERROR(INDEX(tblMaterial[Meldebestand],MATCH(B11,tblMaterial[SAP],0)),"?")) | F11: =IF(OR(B11="",NOT(ISNUMBER(D11))),"",IF(D11<E11,"JA",""))
A12: =IFERROR(INDEX(tblStellplatz[Stellplatz],ROW()-1),"") | B12: =IFERROR(INDEX(tblStellplatz[SAP],ROW()-1),"") | C12: =IF(B12="","",IFERROR(INDEX(tblMaterial[Bezeichnung],MATCH(B12,tblMaterial[SAP],0)),"?")) | D12: =IF(B12="","",IFERROR(INDEX(tblMaterial[Lagerstand],MATCH(B12,tblMaterial[SAP],0)),"?")) | E12: =IF(B12="","",IFERROR(INDEX(tblMaterial[Meldebestand],MATCH(B12,tblMaterial[SAP],0)),"?")) | F12: =IF(OR(B12="",NOT(ISNUMBER(D12))),"",IF(D12<E12,"JA",""))
A13: =IFERROR(INDEX(tblStellplatz[Stellplatz],ROW()-1),"") | B13: =IFERROR(INDEX(tblStellplatz[SAP],ROW()-1),"") | C13: =IF(B13="","",IFERROR(INDEX(tblMaterial[Bezeichnung],MATCH(B13,tblMaterial[SAP],0)),"?")) | D13: =IF(B13="","",IFERROR(INDEX(tblMaterial[Lagerstand],MATCH(B13,tblMaterial[SAP],0)),"?")) | E13: =IF(B13="","",IFERROR(INDEX(tblMaterial[Meldebestand],MATCH(B13,tblMaterial[SAP],0)),"?")) | F13: =IF(OR(B13="",NOT(ISNUMBER(D13))),"",IF(D13<E13,"JA",""))
... A1001: =IFERROR(INDEX(tblStellplatz[Stellplatz],ROW()-1),"") | B1001: =IFERROR(INDEX(tblStellplatz[SAP],ROW()-1),"") | C1001: =IF(B1001="","",IFERROR(INDEX(tblMaterial[Bezeichnung],MATCH(B1001,tblMaterial[SAP],0)),"?")) | D1001: =IF(B1001="","",IFERROR(INDEX(tblMaterial[Lagerstand],MATCH(B1001,tblMaterial[SAP],0)),"?")) | E1001: =IF(B1001="","",IFERROR(INDEX(tblMaterial[Meldebestand],MATCH(B1001,tblMaterial[SAP],0)),"?")) | F1001: =IF(OR(B1001="",NOT(ISNUMBER(D1001))),"",IF(D1001<E1001,"JA",""))

Sheet PlanLayout
A1: Hier die Stellplatz-Nummern so eintragen, wie das Lager wirklich aussieht (ab B2). Leere Zellen = Gang/Wand.
B3: 1 | C3: 2 | D3: 3 | E3: 4 | F3: 5 | G3: 6 | H3: 7 | I3: 8 | J3: 9 | K3: 10 | L3: 11 | M3: 12 | N3: 13 | O3: 14 | P3: 15 | Q3: 16 | R3: 17 | S3: 18 | T3: 19 | U3: 20
B4: 21 | C4: 22 | D4: 23 | E4: 24 | F4: 25 | G4: 26 | H4: 27 | I4: 28 | J4: 29 | K4: 30 | L4: 31 | M4: 32 | N4: 33 | O4: 34 | P4: 35 | Q4: 36 | R4: 37 | S4: 38 | T4: 39 | U4: 40
B6: 41 | C6: 42 | D6: 43 | E6: 44 | F6: 45 | G6: 46 | H6: 47 | I6: 48 | J6: 49 | K6: 50 | L6: 51 | M6: 52 | N6: 53 | O6: 54 | P6: 55 | Q6: 56 | R6: 57 | S6: 58 | T6: 59 | U6: 60
B7: 61 | C7: 62 | D7: 63 | E7: 64 | F7: 65 | G7: 66 | H7: 67 | I7: 68 | J7: 69 | K7: 70 | L7: 71 | M7: 72 | N7: 73 | O7: 74 | P7: 75 | Q7: 76 | R7: 77 | S7: 78 | T7: 79 | U7: 80
B9: 81 | C9: 82 | D9: 83 | E9: 84 | F9: 85 | G9: 86 | H9: 87 | I9: 88 | J9: 89 | K9: 90 | L9: 91 | M9: 92 | N9: 93 | O9: 94 | P9: 95 | Q9: 96 | R9: 97 | S9: 98 | T9: 99 | U9: 100
B10: 101 | C10: 102 | D10: 103 | E10: 104 | F10: 105 | G10: 106 | H10: 107 | I10: 108 | J10: 109 | K10: 110 | L10: 111 | M10: 112 | N10: 113 | O10: 114 | P10: 115 | Q10: 116 | R10: 117 | S10: 118 | T10: 119 | U10: 120
B12: 121 | C12: 122 | D12: 123 | E12: 124 | F12: 125 | G12: 126 | H12: 127 | I12: 128 | J12: 129 | K12: 130 | L12: 131 | M12: 132 | N12: 133 | O12: 134 | P12: 135 | Q12: 136 | R12: 137 | S12: 138 | T12: 139 | U12: 140
B13: 141 | C13: 142 | D13: 143 | E13: 144 | F13: 145 | G13: 146 | H13: 147 | I13: 148 | J13: 149 | K13: 150 | L13: 151 | M13: 152 | N13: 153 | O13: 154 | P13: 155 | Q13: 156 | R13: 157 | S13: 158 | T13: 159 | U13: 160
B15: 161 | C15: 162 | D15: 163 | E15: 164 | F15: 165 | G15: 166 | H15: 167 | I15: 168 | J15: 169 | K15: 170 | L15: 171 | M15: 172 | N15: 173 | O15: 174 | P15: 175 | Q15: 176 | R15: 177 | S15: 178 | T15: 179 | U15: 180
B16: 181 | C16: 182 | D16: 183 | E16: 184 | F16: 185 | G16: 186 | H16: 187 | I16: 188 | J16: 189 | K16: 190 | L16: 191 | M16: 192 | N16: 193 | O16: 194 | P16: 195 | Q16: 196 | R16: 197 | S16: 198 | T16: 199 | U16: 200

Sheet Lagerplan
A1: Lagerplan (nur lesen) – Platz / MN
B2: =IF(PlanLayout!B2="","",PlanLayout!B2&CHAR(10)&IFERROR(IF(INDEX(tblStellplatz[SAP],MATCH(PlanLayout!B2,tblStellplatz[Stellplatz],0))="","leer",IF(LEFT(RIGHT(INDEX(tblStellplatz[SAP],MATCH(PlanLayout!B2,tblStellplatz[Stellplatz],0)),4),1)="0",RIGHT(INDEX(tblStellplatz[SAP],MATCH(PlanLayout!B2,tblStellplatz[Stellplatz],0)),5),RIGHT(INDEX(tblStellplatz[SAP],MATCH(PlanLayout!B2,tblStellplatz[Stellplatz],0)),4))),"?")) | C2: =IF(PlanLayout!C2="","",PlanLayout!C2&CHAR(10)&IFERROR(IF(INDEX(tblStellplatz[SAP],MATCH(PlanLayout!C2,tblStellplatz[Stellplatz],0))="","leer",IF(LEFT(RIGHT(INDEX(tblStellplatz[SAP],MATCH(PlanLayout!C2,tblStellplatz[Stellplatz],0)),4),1)="0",RIGHT(INDEX(tblStellplatz[SAP],MATCH(PlanLayout!C2,tblStellplatz[Stellplatz],0)),5),RIGHT(INDEX(tblStellplatz[SAP],MATCH(PlanLayout!C2,tblStellplatz[Stellplatz],0)),4))),"?")) | D2: =IF(PlanLayout!D2="","",PlanLayout!D2&CHAR(10)&IFERROR(IF(INDEX(tblStellplatz[SAP],MATCH(PlanLayout!D2,tblStellplatz[Stellplatz],0))="","leer",IF(LEFT(RIGHT(INDEX(tblStellplatz[SAP],MATCH(PlanLayout!D2,tblStellplatz[Stellplatz],0)),4),1)="0",RIGHT(INDEX(tblStellplatz[SAP],MATCH(PlanLayout!D2,tblStellplatz[Stellplatz],0)),5),RIGHT(INDEX(tblStellplatz[SAP],MATCH(PlanLayout!D2,tblStellplatz[Stellplatz],0)),4))),"?")) | E2: =IF(PlanLayout!E2="","",PlanLayout!E2&CHAR(10)&IFERROR(IF(INDEX(tblStellplatz[SAP],MATCH(PlanLayout!E2,tblStellplatz[Stellplatz],0))="","leer",IF(LEFT(RIGHT(INDEX(tblStellplatz[SAP],MATCH(PlanLayout!E2,tblStellplatz[Stellplatz],0)),4),1)="0",RIGHT(INDEX(tblStellplatz[SAP],MATCH(PlanLayout!E2,tblStellplatz[Stellplatz],0)),5),RIGHT(INDEX(tblStellplatz[SAP],MATCH(PlanLayout!E2,tblStellplatz[Stellplatz],0)),4))),"?")) | F2: =IF(PlanLayout!F2="","",PlanLayout!F2&CHAR(10)&IFERROR(IF(INDEX(tblStellplatz[SAP],MATCH(PlanLayout!F2,tblStellplatz[Stellplatz],0))="","leer",IF(LEFT(RIGHT(INDEX(tblStellplatz[SAP],MATCH(PlanLayout!F2,tblStellplatz[Stellplatz],0)),4),1)="0",RIGHT(INDEX(tblStellplatz[SAP],MATCH(PlanLayout!F2,tblStellplatz[Stellplatz],0)),5),RIGHT(INDEX(tblStellplatz[SAP],MATCH(PlanLayout!F2,tblStellplatz[Stellplatz],0)),4))),"?")) | G2: =IF(PlanLayout!G2="","",PlanLayout!G2&CHAR(10)&IFERROR(IF(INDEX(tblStellplatz[SAP],MATCH(PlanLayout!G2,tblStellplatz[Stellplatz],0))="","leer",IF(LEFT(RIGHT(INDEX(tblStellplatz[SAP],MATCH(PlanLayout!G2,tblStellplatz[Stellplatz],0)),4),1)="0",RIGHT(INDEX(tblStellplatz[SAP],MATCH(PlanLayout!G2,tblStellplatz[Stellplatz],0)),5),RIGHT(INDEX(tblStellplatz[SAP],MATCH(PlanLayout!G2,tblStellplatz[Stellplatz],0)),4))),"?")) | H2: =IF(PlanLayout!H2="","",PlanLayout!H2&CHAR(10)&IFERROR(IF(INDEX(tblStellplatz[SAP],MATCH(PlanLayout!H2,tblStellplatz[Stellplatz],0))="","leer",IF(LEFT(RIGHT(INDEX(tblStellplatz[SAP],MATCH(PlanLayout!H2,tblStellplatz[Stellplatz],0)),4),1)="0",RIGHT(INDEX(tblStellplatz[SAP],MATCH(PlanLayout!H2,tblStellplatz[Stellplatz],0)),5),RIGHT(INDEX(tblStellplatz[SAP],MATCH(PlanLayout!H2,tblStellplatz[Stellplatz],0)),4))),"?")) | I2: =IF(PlanLayout!I2="","",PlanLayout!I2&CHAR(10)&IFERROR(IF(INDEX(tblStellplatz[SAP],MATCH(PlanLayout!I2,tblStellplatz[Stellplatz],0))="","leer",IF(LEFT(RIGHT(INDEX(tblStellplatz[SAP],MATCH(PlanLayout!I2,tblStellplatz[Stellplatz],0)),4),1)="0",RIGHT(INDEX(tblStellplatz[SAP],MATCH(PlanLayout!I2,tblStellplatz[Stellplatz],0)),5),RIGHT(INDEX(tblStellplatz[SAP],MATCH(PlanLayout!I2,tblStellplatz[Stellplatz],0)),4))),"?")) | ... AO2: =IF(PlanLayout!AO2="","",PlanLayout!AO2&CHAR(10)&IFERROR(IF(INDEX(tblStellplatz[SAP],MATCH(PlanLayout!AO2,tblStellplatz[Stellplatz],0))="","leer",IF(LEFT(RIGHT(INDEX(tblStellplatz[SAP],MATCH(PlanLayout!AO2,tblStellplatz[Stellplatz],0)),4),1)="0",RIGHT(INDEX(tblStellplatz[SAP],MATCH(PlanLayout!AO2,tblStellplatz[Stellplatz],0)),5),RIGHT(INDEX(tblStellplatz[SAP],MATCH(PlanLayout!AO2,tblStellplatz[Stellplatz],0)),4))),"?"))
B3: =IF(PlanLayout!B3="","",PlanLayout!B3&CHAR(10)&IFERROR(IF(INDEX(tblStellplatz[SAP],MATCH(PlanLayout!B3,tblStellplatz[Stellplatz],0))="","leer",IF(LEFT(RIGHT(INDEX(tblStellplatz[SAP],MATCH(PlanLayout!B3,tblStellplatz[Stellplatz],0)),4),1)="0",RIGHT(INDEX(tblStellplatz[SAP],MATCH(PlanLayout!B3,tblStellplatz[Stellplatz],0)),5),RIGHT(INDEX(tblStellplatz[SAP],MATCH(PlanLayout!B3,tblStellplatz[Stellplatz],0)),4))),"?")) | C3: =IF(PlanLayout!C3="","",PlanLayout!C3&CHAR(10)&IFERROR(IF(INDEX(tblStellplatz[SAP],MATCH(PlanLayout!C3,tblStellplatz[Stellplatz],0))="","leer",IF(LEFT(RIGHT(INDEX(tblStellplatz[SAP],MATCH(PlanLayout!C3,tblStellplatz[Stellplatz],0)),4),1)="0",RIGHT(INDEX(tblStellplatz[SAP],MATCH(PlanLayout!C3,tblStellplatz[Stellplatz],0)),5),RIGHT(INDEX(tblStellplatz[SAP],MATCH(PlanLayout!C3,tblStellplatz[Stellplatz],0)),4))),"?")) | D3: =IF(PlanLayout!D3="","",PlanLayout!D3&CHAR(10)&IFERROR(IF(INDEX(tblStellplatz[SAP],MATCH(PlanLayout!D3,tblStellplatz[Stellplatz],0))="","leer",IF(LEFT(RIGHT(INDEX(tblStellplatz[SAP],MATCH(PlanLayout!D3,tblStellplatz[Stellplatz],0)),4),1)="0",RIGHT(INDEX(tblStellplatz[SAP],MATCH(PlanLayout!D3,tblStellplatz[Stellplatz],0)),5),RIGHT(INDEX(tblStellplatz[SAP],MATCH(PlanLayout!D3,tblStellplatz[Stellplatz],0)),4))),"?")) | E3: =IF(PlanLayout!E3="","",PlanLayout!E3&CHAR(10)&IFERROR(IF(INDEX(tblStellplatz[SAP],MATCH(PlanLayout!E3,tblStellplatz[Stellplatz],0))="","leer",IF(LEFT(RIGHT(INDEX(tblStellplatz[SAP],MATCH(PlanLayout!E3,tblStellplatz[Stellplatz],0)),4),1)="0",RIGHT(INDEX(tblStellplatz[SAP],MATCH(PlanLayout!E3,tblStellplatz[Stellplatz],0)),5),RIGHT(INDEX(tblStellplatz[SAP],MATCH(PlanLayout!E3,tblStellplatz[Stellplatz],0)),4))),"?")) | F3: =IF(PlanLayout!F3="","",PlanLayout!F3&CHAR(10)&IFERROR(IF(INDEX(tblStellplatz[SAP],MATCH(PlanLayout!F3,tblStellplatz[Stellplatz],0))="","leer",IF(LEFT(RIGHT(INDEX(tblStellplatz[SAP],MATCH(PlanLayout!F3,tblStellplatz[Stellplatz],0)),4),1)="0",RIGHT(INDEX(tblStellplatz[SAP],MATCH(PlanLayout!F3,tblStellplatz[Stellplatz],0)),5),RIGHT(INDEX(tblStellplatz[SAP],MATCH(PlanLayout!F3,tblStellplatz[Stellplatz],0)),4))),"?")) | G3: =IF(PlanLayout!G3="","",PlanLayout!G3&CHAR(10)&IFERROR(IF(INDEX(tblStellplatz[SAP],MATCH(PlanLayout!G3,tblStellplatz[Stellplatz],0))="","leer",IF(LEFT(RIGHT(INDEX(tblStellplatz[SAP],MATCH(PlanLayout!G3,tblStellplatz[Stellplatz],0)),4),1)="0",RIGHT(INDEX(tblStellplatz[SAP],MATCH(PlanLayout!G3,tblStellplatz[Stellplatz],0)),5),RIGHT(INDEX(tblStellplatz[SAP],MATCH(PlanLayout!G3,tblStellplatz[Stellplatz],0)),4))),"?")) | H3: =IF(PlanLayout!H3="","",PlanLayout!H3&CHAR(10)&IFERROR(IF(INDEX(tblStellplatz[SAP],MATCH(PlanLayout!H3,tblStellplatz[Stellplatz],0))="","leer",IF(LEFT(RIGHT(INDEX(tblStellplatz[SAP],MATCH(PlanLayout!H3,tblStellplatz[Stellplatz],0)),4),1)="0",RIGHT(INDEX(tblStellplatz[SAP],MATCH(PlanLayout!H3,tblStellplatz[Stellplatz],0)),5),RIGHT(INDEX(tblStellplatz[SAP],MATCH(PlanLayout!H3,tblStellplatz[Stellplatz],0)),4))),"?")) | I3: =IF(PlanLayout!I3="","",PlanLayout!I3&CHAR(10)&IFERROR(IF(INDEX(tblStellplatz[SAP],MATCH(PlanLayout!I3,tblStellplatz[Stellplatz],0))="","leer",IF(LEFT(RIGHT(INDEX(tblStellplatz[SAP],MATCH(PlanLayout!I3,tblStellplatz[Stellplatz],0)),4),1)="0",RIGHT(INDEX(tblStellplatz[SAP],MATCH(PlanLayout!I3,tblStellplatz[Stellplatz],0)),5),RIGHT(INDEX(tblStellplatz[SAP],MATCH(PlanLayout!I3,tblStellplatz[Stellplatz],0)),4))),"?")) | ... AO3: =IF(PlanLayout!AO3="","",PlanLayout!AO3&CHAR(10)&IFERROR(IF(INDEX(tblStellplatz[SAP],MATCH(PlanLayout!AO3,tblStellplatz[Stellplatz],0))="","leer",IF(LEFT(RIGHT(INDEX(tblStellplatz[SAP],MATCH(PlanLayout!AO3,tblStellplatz[Stellplatz],0)),4),1)="0",RIGHT(INDEX(tblStellplatz[SAP],MATCH(PlanLayout!AO3,tblStellplatz[Stellplatz],0)),5),RIGHT(INDEX(tblStellplatz[SAP],MATCH(PlanLayout!AO3,tblStellplatz[Stellplatz],0)),4))),"?"))
B4: =IF(PlanLayout!B4="","",PlanLayout!B4&CHAR(10)&IFERROR(IF(INDEX(tblStellplatz[SAP],MATCH(PlanLayout!B4,tblStellplatz[Stellplatz],0))="","leer",IF(LEFT(RIGHT(INDEX(tblStellplatz[SAP],MATCH(PlanLayout!B4,tblStellplatz[Stellplatz],0)),4),1)="0",RIGHT(INDEX(tblStellplatz[SAP],MATCH(PlanLayout!B4,tblStellplatz[Stellplatz],0)),5),RIGHT(INDEX(tblStellplatz[SAP],MATCH(PlanLayout!B4,tblStellplatz[Stellplatz],0)),4))),"?")) | C4: =IF(PlanLayout!C4="","",PlanLayout!C4&CHAR(10)&IFERROR(IF(INDEX(tblStellplatz[SAP],MATCH(PlanLayout!C4,tblStellplatz[Stellplatz],0))="","leer",IF(LEFT(RIGHT(INDEX(tblStellplatz[SAP],MATCH(PlanLayout!C4,tblStellplatz[Stellplatz],0)),4),1)="0",RIGHT(INDEX(tblStellplatz[SAP],MATCH(PlanLayout!C4,tblStellplatz[Stellplatz],0)),5),RIGHT(INDEX(tblStellplatz[SAP],MATCH(PlanLayout!C4,tblStellplatz[Stellplatz],0)),4))),"?")) | D4: =IF(PlanLayout!D4="","",PlanLayout!D4&CHAR(10)&IFERROR(IF(INDEX(tblStellplatz[SAP],MATCH(PlanLayout!D4,tblStellplatz[Stellplatz],0))="","leer",IF(LEFT(RIGHT(INDEX(tblStellplatz[SAP],MATCH(PlanLayout!D4,tblStellplatz[Stellplatz],0)),4),1)="0",RIGHT(INDEX(tblStellplatz[SAP],MATCH(PlanLayout!D4,tblStellplatz[Stellplatz],0)),5),RIGHT(INDEX(tblStellplatz[SAP],MATCH(PlanLayout!D4,tblStellplatz[Stellplatz],0)),4))),"?")) | E4: =IF(PlanLayout!E4="","",PlanLayout!E4&CHAR(10)&IFERROR(IF(INDEX(tblStellplatz[SAP],MATCH(PlanLayout!E4,tblStellplatz[Stellplatz],0))="","leer",IF(LEFT(RIGHT(INDEX(tblStellplatz[SAP],MATCH(PlanLayout!E4,tblStellplatz[Stellplatz],0)),4),1)="0",RIGHT(INDEX(tblStellplatz[SAP],MATCH(PlanLayout!E4,tblStellplatz[Stellplatz],0)),5),RIGHT(INDEX(tblStellplatz[SAP],MATCH(PlanLayout!E4,tblStellplatz[Stellplatz],0)),4))),"?")) | F4: =IF(PlanLayout!F4="","",PlanLayout!F4&CHAR(10)&IFERROR(IF(INDEX(tblStellplatz[SAP],MATCH(PlanLayout!F4,tblStellplatz[Stellplatz],0))="","leer",IF(LEFT(RIGHT(INDEX(tblStellplatz[SAP],MATCH(PlanLayout!F4,tblStellplatz[Stellplatz],0)),4),1)="0",RIGHT(INDEX(tblStellplatz[SAP],MATCH(PlanLayout!F4,tblStellplatz[Stellplatz],0)),5),RIGHT(INDEX(tblStellplatz[SAP],MATCH(PlanLayout!F4,tblStellplatz[Stellplatz],0)),4))),"?")) | G4: =IF(PlanLayout!G4="","",PlanLayout!G4&CHAR(10)&IFERROR(IF(INDEX(tblStellplatz[SAP],MATCH(PlanLayout!G4,tblStellplatz[Stellplatz],0))="","leer",IF(LEFT(RIGHT(INDEX(tblStellplatz[SAP],MATCH(PlanLayout!G4,tblStellplatz[Stellplatz],0)),4),1)="0",RIGHT(INDEX(tblStellplatz[SAP],MATCH(PlanLayout!G4,tblStellplatz[Stellplatz],0)),5),RIGHT(INDEX(tblStellplatz[SAP],MATCH(PlanLayout!G4,tblStellplatz[Stellplatz],0)),4))),"?")) | H4: =IF(PlanLayout!H4="","",PlanLayout!H4&CHAR(10)&IFERROR(IF(INDEX(tblStellplatz[SAP],MATCH(PlanLayout!H4,tblStellplatz[Stellplatz],0))="","leer",IF(LEFT(RIGHT(INDEX(tblStellplatz[SAP],MATCH(PlanLayout!H4,tblStellplatz[Stellplatz],0)),4),1)="0",RIGHT(INDEX(tblStellplatz[SAP],MATCH(PlanLayout!H4,tblStellplatz[Stellplatz],0)),5),RIGHT(INDEX(tblStellplatz[SAP],MATCH(PlanLayout!H4,tblStellplatz[Stellplatz],0)),4))),"?")) | I4: =IF(PlanLayout!I4="","",PlanLayout!I4&CHAR(10)&IFERROR(IF(INDEX(tblStellplatz[SAP],MATCH(PlanLayout!I4,tblStellplatz[Stellplatz],0))="","leer",IF(LEFT(RIGHT(INDEX(tblStellplatz[SAP],MATCH(PlanLayout!I4,tblStellplatz[Stellplatz],0)),4),1)="0",RIGHT(INDEX(tblStellplatz[SAP],MATCH(PlanLayout!I4,tblStellplatz[Stellplatz],0)),5),RIGHT(INDEX(tblStellplatz[SAP],MATCH(PlanLayout!I4,tblStellplatz[Stellplatz],0)),4))),"?")) | ... AO4: =IF(PlanLayout!AO4="","",PlanLayout!AO4&CHAR(10)&IFERROR(IF(INDEX(tblStellplatz[SAP],MATCH(PlanLayout!AO4,tblStellplatz[Stellplatz],0))="","leer",IF(LEFT(RIGHT(INDEX(tblStellplatz[SAP],MATCH(PlanLayout!AO4,tblStellplatz[Stellplatz],0)),4),1)="0",RIGHT(INDEX(tblStellplatz[SAP],MATCH(PlanLayout!AO4,tblStellplatz[Stellplatz],0)),5),RIGHT(INDEX(tblStellplatz[SAP],MATCH(PlanLayout!AO4,tblStellplatz[Stellplatz],0)),4))),"?"))
B5: =IF(PlanLayout!B5="","",PlanLayout!B5&CHAR(10)&IFERROR(IF(INDEX(tblStellplatz[SAP],MATCH(PlanLayout!B5,tblStellplatz[Stellplatz],0))="","leer",IF(LEFT(RIGHT(INDEX(tblStellplatz[SAP],MATCH(PlanLayout!B5,tblStellplatz[Stellplatz],0)),4),1)="0",RIGHT(INDEX(tblStellplatz[SAP],MATCH(PlanLayout!B5,tblStellplatz[Stellplatz],0)),5),RIGHT(INDEX(tblStellplatz[SAP],MATCH(PlanLayout!B5,tblStellplatz[Stellplatz],0)),4))),"?")) | C5: =IF(PlanLayout!C5="","",PlanLayout!C5&CHAR(10)&IFERROR(IF(INDEX(tblStellplatz[SAP],MATCH(PlanLayout!C5,tblStellplatz[Stellplatz],0))="","leer",IF(LEFT(RIGHT(INDEX(tblStellplatz[SAP],MATCH(PlanLayout!C5,tblStellplatz[Stellplatz],0)),4),1)="0",RIGHT(INDEX(tblStellplatz[SAP],MATCH(PlanLayout!C5,tblStellplatz[Stellplatz],0)),5),RIGHT(INDEX(tblStellplatz[SAP],MATCH(PlanLayout!C5,tblStellplatz[Stellplatz],0)),4))),"?")) | D5: =IF(PlanLayout!D5="","",PlanLayout!D5&CHAR(10)&IFERROR(IF(INDEX(tblStellplatz[SAP],MATCH(PlanLayout!D5,tblStellplatz[Stellplatz],0))="","leer",IF(LEFT(RIGHT(INDEX(tblStellplatz[SAP],MATCH(PlanLayout!D5,tblStellplatz[Stellplatz],0)),4),1)="0",RIGHT(INDEX(tblStellplatz[SAP],MATCH(PlanLayout!D5,tblStellplatz[Stellplatz],0)),5),RIGHT(INDEX(tblStellplatz[SAP],MATCH(PlanLayout!D5,tblStellplatz[Stellplatz],0)),4))),"?")) | E5: =IF(PlanLayout!E5="","",PlanLayout!E5&CHAR(10)&IFERROR(IF(INDEX(tblStellplatz[SAP],MATCH(PlanLayout!E5,tblStellplatz[Stellplatz],0))="","leer",IF(LEFT(RIGHT(INDEX(tblStellplatz[SAP],MATCH(PlanLayout!E5,tblStellplatz[Stellplatz],0)),4),1)="0",RIGHT(INDEX(tblStellplatz[SAP],MATCH(PlanLayout!E5,tblStellplatz[Stellplatz],0)),5),RIGHT(INDEX(tblStellplatz[SAP],MATCH(PlanLayout!E5,tblStellplatz[Stellplatz],0)),4))),"?")) | F5: =IF(PlanLayout!F5="","",PlanLayout!F5&CHAR(10)&IFERROR(IF(INDEX(tblStellplatz[SAP],MATCH(PlanLayout!F5,tblStellplatz[Stellplatz],0))="","leer",IF(LEFT(RIGHT(INDEX(tblStellplatz[SAP],MATCH(PlanLayout!F5,tblStellplatz[Stellplatz],0)),4),1)="0",RIGHT(INDEX(tblStellplatz[SAP],MATCH(PlanLayout!F5,tblStellplatz[Stellplatz],0)),5),RIGHT(INDEX(tblStellplatz[SAP],MATCH(PlanLayout!F5,tblStellplatz[Stellplatz],0)),4))),"?")) | G5: =IF(PlanLayout!G5="","",PlanLayout!G5&CHAR(10)&IFERROR(IF(INDEX(tblStellplatz[SAP],MATCH(PlanLayout!G5,tblStellplatz[Stellplatz],0))="","leer",IF(LEFT(RIGHT(INDEX(tblStellplatz[SAP],MATCH(PlanLayout!G5,tblStellplatz[Stellplatz],0)),4),1)="0",RIGHT(INDEX(tblStellplatz[SAP],MATCH(PlanLayout!G5,tblStellplatz[Stellplatz],0)),5),RIGHT(INDEX(tblStellplatz[SAP],MATCH(PlanLayout!G5,tblStellplatz[Stellplatz],0)),4))),"?")) | H5: =IF(PlanLayout!H5="","",PlanLayout!H5&CHAR(10)&IFERROR(IF(INDEX(tblStellplatz[SAP],MATCH(PlanLayout!H5,tblStellplatz[Stellplatz],0))="","leer",IF(LEFT(RIGHT(INDEX(tblStellplatz[SAP],MATCH(PlanLayout!H5,tblStellplatz[Stellplatz],0)),4),1)="0",RIGHT(INDEX(tblStellplatz[SAP],MATCH(PlanLayout!H5,tblStellplatz[Stellplatz],0)),5),RIGHT(INDEX(tblStellplatz[SAP],MATCH(PlanLayout!H5,tblStellplatz[Stellplatz],0)),4))),"?")) | I5: =IF(PlanLayout!I5="","",PlanLayout!I5&CHAR(10)&IFERROR(IF(INDEX(tblStellplatz[SAP],MATCH(PlanLayout!I5,tblStellplatz[Stellplatz],0))="","leer",IF(LEFT(RIGHT(INDEX(tblStellplatz[SAP],MATCH(PlanLayout!I5,tblStellplatz[Stellplatz],0)),4),1)="0",RIGHT(INDEX(tblStellplatz[SAP],MATCH(PlanLayout!I5,tblStellplatz[Stellplatz],0)),5),RIGHT(INDEX(tblStellplatz[SAP],MATCH(PlanLayout!I5,tblStellplatz[Stellplatz],0)),4))),"?")) | ... AO5: =IF(PlanLayout!AO5="","",PlanLayout!AO5&CHAR(10)&IFERROR(IF(INDEX(tblStellplatz[SAP],MATCH(PlanLayout!AO5,tblStellplatz[Stellplatz],0))="","leer",IF(LEFT(RIGHT(INDEX(tblStellplatz[SAP],MATCH(PlanLayout!AO5,tblStellplatz[Stellplatz],0)),4),1)="0",RIGHT(INDEX(tblStellplatz[SAP],MATCH(PlanLayout!AO5,tblStellplatz[Stellplatz],0)),5),RIGHT(INDEX(tblStellplatz[SAP],MATCH(PlanLayout!AO5,tblStellplatz[Stellplatz],0)),4))),"?"))
B6: =IF(PlanLayout!B6="","",PlanLayout!B6&CHAR(10)&IFERROR(IF(INDEX(tblStellplatz[SAP],MATCH(PlanLayout!B6,tblStellplatz[Stellplatz],0))="","leer",IF(LEFT(RIGHT(INDEX(tblStellplatz[SAP],MATCH(PlanLayout!B6,tblStellplatz[Stellplatz],0)),4),1)="0",RIGHT(INDEX(tblStellplatz[SAP],MATCH(PlanLayout!B6,tblStellplatz[Stellplatz],0)),5),RIGHT(INDEX(tblStellplatz[SAP],MATCH(PlanLayout!B6,tblStellplatz[Stellplatz],0)),4))),"?")) | C6: =IF(PlanLayout!C6="","",PlanLayout!C6&CHAR(10)&IFERROR(IF(INDEX(tblStellplatz[SAP],MATCH(PlanLayout!C6,tblStellplatz[Stellplatz],0))="","leer",IF(LEFT(RIGHT(INDEX(tblStellplatz[SAP],MATCH(PlanLayout!C6,tblStellplatz[Stellplatz],0)),4),1)="0",RIGHT(INDEX(tblStellplatz[SAP],MATCH(PlanLayout!C6,tblStellplatz[Stellplatz],0)),5),RIGHT(INDEX(tblStellplatz[SAP],MATCH(PlanLayout!C6,tblStellplatz[Stellplatz],0)),4))),"?")) | D6: =IF(PlanLayout!D6="","",PlanLayout!D6&CHAR(10)&IFERROR(IF(INDEX(tblStellplatz[SAP],MATCH(PlanLayout!D6,tblStellplatz[Stellplatz],0))="","leer",IF(LEFT(RIGHT(INDEX(tblStellplatz[SAP],MATCH(PlanLayout!D6,tblStellplatz[Stellplatz],0)),4),1)="0",RIGHT(INDEX(tblStellplatz[SAP],MATCH(PlanLayout!D6,tblStellplatz[Stellplatz],0)),5),RIGHT(INDEX(tblStellplatz[SAP],MATCH(PlanLayout!D6,tblStellplatz[Stellplatz],0)),4))),"?")) | E6: =IF(PlanLayout!E6="","",PlanLayout!E6&CHAR(10)&IFERROR(IF(INDEX(tblStellplatz[SAP],MATCH(PlanLayout!E6,tblStellplatz[Stellplatz],0))="","leer",IF(LEFT(RIGHT(INDEX(tblStellplatz[SAP],MATCH(PlanLayout!E6,tblStellplatz[Stellplatz],0)),4),1)="0",RIGHT(INDEX(tblStellplatz[SAP],MATCH(PlanLayout!E6,tblStellplatz[Stellplatz],0)),5),RIGHT(INDEX(tblStellplatz[SAP],MATCH(PlanLayout!E6,tblStellplatz[Stellplatz],0)),4))),"?")) | F6: =IF(PlanLayout!F6="","",PlanLayout!F6&CHAR(10)&IFERROR(IF(INDEX(tblStellplatz[SAP],MATCH(PlanLayout!F6,tblStellplatz[Stellplatz],0))="","leer",IF(LEFT(RIGHT(INDEX(tblStellplatz[SAP],MATCH(PlanLayout!F6,tblStellplatz[Stellplatz],0)),4),1)="0",RIGHT(INDEX(tblStellplatz[SAP],MATCH(PlanLayout!F6,tblStellplatz[Stellplatz],0)),5),RIGHT(INDEX(tblStellplatz[SAP],MATCH(PlanLayout!F6,tblStellplatz[Stellplatz],0)),4))),"?")) | G6: =IF(PlanLayout!G6="","",PlanLayout!G6&CHAR(10)&IFERROR(IF(INDEX(tblStellplatz[SAP],MATCH(PlanLayout!G6,tblStellplatz[Stellplatz],0))="","leer",IF(LEFT(RIGHT(INDEX(tblStellplatz[SAP],MATCH(PlanLayout!G6,tblStellplatz[Stellplatz],0)),4),1)="0",RIGHT(INDEX(tblStellplatz[SAP],MATCH(PlanLayout!G6,tblStellplatz[Stellplatz],0)),5),RIGHT(INDEX(tblStellplatz[SAP],MATCH(PlanLayout!G6,tblStellplatz[Stellplatz],0)),4))),"?")) | H6: =IF(PlanLayout!H6="","",PlanLayout!H6&CHAR(10)&IFERROR(IF(INDEX(tblStellplatz[SAP],MATCH(PlanLayout!H6,tblStellplatz[Stellplatz],0))="","leer",IF(LEFT(RIGHT(INDEX(tblStellplatz[SAP],MATCH(PlanLayout!H6,tblStellplatz[Stellplatz],0)),4),1)="0",RIGHT(INDEX(tblStellplatz[SAP],MATCH(PlanLayout!H6,tblStellplatz[Stellplatz],0)),5),RIGHT(INDEX(tblStellplatz[SAP],MATCH(PlanLayout!H6,tblStellplatz[Stellplatz],0)),4))),"?")) | I6: =IF(PlanLayout!I6="","",PlanLayout!I6&CHAR(10)&IFERROR(IF(INDEX(tblStellplatz[SAP],MATCH(PlanLayout!I6,tblStellplatz[Stellplatz],0))="","leer",IF(LEFT(RIGHT(INDEX(tblStellplatz[SAP],MATCH(PlanLayout!I6,tblStellplatz[Stellplatz],0)),4),1)="0",RIGHT(INDEX(tblStellplatz[SAP],MATCH(PlanLayout!I6,tblStellplatz[Stellplatz],0)),5),RIGHT(INDEX(tblStellplatz[SAP],MATCH(PlanLayout!I6,tblStellplatz[Stellplatz],0)),4))),"?")) | ... AO6: =IF(PlanLayout!AO6="","",PlanLayout!AO6&CHAR(10)&IFERROR(IF(INDEX(tblStellplatz[SAP],MATCH(PlanLayout!AO6,tblStellplatz[Stellplatz],0))="","leer",IF(LEFT(RIGHT(INDEX(tblStellplatz[SAP],MATCH(PlanLayout!AO6,tblStellplatz[Stellplatz],0)),4),1)="0",RIGHT(INDEX(tblStellplatz[SAP],MATCH(PlanLayout!AO6,tblStellplatz[Stellplatz],0)),5),RIGHT(INDEX(tblStellplatz[SAP],MATCH(PlanLayout!AO6,tblStellplatz[Stellplatz],0)),4))),"?"))
B7: =IF(PlanLayout!B7="","",PlanLayout!B7&CHAR(10)&IFERROR(IF(INDEX(tblStellplatz[SAP],MATCH(PlanLayout!B7,tblStellplatz[Stellplatz],0))="","leer",IF(LEFT(RIGHT(INDEX(tblStellplatz[SAP],MATCH(PlanLayout!B7,tblStellplatz[Stellplatz],0)),4),1)="0",RIGHT(INDEX(tblStellplatz[SAP],MATCH(PlanLayout!B7,tblStellplatz[Stellplatz],0)),5),RIGHT(INDEX(tblStellplatz[SAP],MATCH(PlanLayout!B7,tblStellplatz[Stellplatz],0)),4))),"?")) | C7: =IF(PlanLayout!C7="","",PlanLayout!C7&CHAR(10)&IFERROR(IF(INDEX(tblStellplatz[SAP],MATCH(PlanLayout!C7,tblStellplatz[Stellplatz],0))="","leer",IF(LEFT(RIGHT(INDEX(tblStellplatz[SAP],MATCH(PlanLayout!C7,tblStellplatz[Stellplatz],0)),4),1)="0",RIGHT(INDEX(tblStellplatz[SAP],MATCH(PlanLayout!C7,tblStellplatz[Stellplatz],0)),5),RIGHT(INDEX(tblStellplatz[SAP],MATCH(PlanLayout!C7,tblStellplatz[Stellplatz],0)),4))),"?")) | D7: =IF(PlanLayout!D7="","",PlanLayout!D7&CHAR(10)&IFERROR(IF(INDEX(tblStellplatz[SAP],MATCH(PlanLayout!D7,tblStellplatz[Stellplatz],0))="","leer",IF(LEFT(RIGHT(INDEX(tblStellplatz[SAP],MATCH(PlanLayout!D7,tblStellplatz[Stellplatz],0)),4),1)="0",RIGHT(INDEX(tblStellplatz[SAP],MATCH(PlanLayout!D7,tblStellplatz[Stellplatz],0)),5),RIGHT(INDEX(tblStellplatz[SAP],MATCH(PlanLayout!D7,tblStellplatz[Stellplatz],0)),4))),"?")) | E7: =IF(PlanLayout!E7="","",PlanLayout!E7&CHAR(10)&IFERROR(IF(INDEX(tblStellplatz[SAP],MATCH(PlanLayout!E7,tblStellplatz[Stellplatz],0))="","leer",IF(LEFT(RIGHT(INDEX(tblStellplatz[SAP],MATCH(PlanLayout!E7,tblStellplatz[Stellplatz],0)),4),1)="0",RIGHT(INDEX(tblStellplatz[SAP],MATCH(PlanLayout!E7,tblStellplatz[Stellplatz],0)),5),RIGHT(INDEX(tblStellplatz[SAP],MATCH(PlanLayout!E7,tblStellplatz[Stellplatz],0)),4))),"?")) | F7: =IF(PlanLayout!F7="","",PlanLayout!F7&CHAR(10)&IFERROR(IF(INDEX(tblStellplatz[SAP],MATCH(PlanLayout!F7,tblStellplatz[Stellplatz],0))="","leer",IF(LEFT(RIGHT(INDEX(tblStellplatz[SAP],MATCH(PlanLayout!F7,tblStellplatz[Stellplatz],0)),4),1)="0",RIGHT(INDEX(tblStellplatz[SAP],MATCH(PlanLayout!F7,tblStellplatz[Stellplatz],0)),5),RIGHT(INDEX(tblStellplatz[SAP],MATCH(PlanLayout!F7,tblStellplatz[Stellplatz],0)),4))),"?")) | G7: =IF(PlanLayout!G7="","",PlanLayout!G7&CHAR(10)&IFERROR(IF(INDEX(tblStellplatz[SAP],MATCH(PlanLayout!G7,tblStellplatz[Stellplatz],0))="","leer",IF(LEFT(RIGHT(INDEX(tblStellplatz[SAP],MATCH(PlanLayout!G7,tblStellplatz[Stellplatz],0)),4),1)="0",RIGHT(INDEX(tblStellplatz[SAP],MATCH(PlanLayout!G7,tblStellplatz[Stellplatz],0)),5),RIGHT(INDEX(tblStellplatz[SAP],MATCH(PlanLayout!G7,tblStellplatz[Stellplatz],0)),4))),"?")) | H7: =IF(PlanLayout!H7="","",PlanLayout!H7&CHAR(10)&IFERROR(IF(INDEX(tblStellplatz[SAP],MATCH(PlanLayout!H7,tblStellplatz[Stellplatz],0))="","leer",IF(LEFT(RIGHT(INDEX(tblStellplatz[SAP],MATCH(PlanLayout!H7,tblStellplatz[Stellplatz],0)),4),1)="0",RIGHT(INDEX(tblStellplatz[SAP],MATCH(PlanLayout!H7,tblStellplatz[Stellplatz],0)),5),RIGHT(INDEX(tblStellplatz[SAP],MATCH(PlanLayout!H7,tblStellplatz[Stellplatz],0)),4))),"?")) | I7: =IF(PlanLayout!I7="","",PlanLayout!I7&CHAR(10)&IFERROR(IF(INDEX(tblStellplatz[SAP],MATCH(PlanLayout!I7,tblStellplatz[Stellplatz],0))="","leer",IF(LEFT(RIGHT(INDEX(tblStellplatz[SAP],MATCH(PlanLayout!I7,tblStellplatz[Stellplatz],0)),4),1)="0",RIGHT(INDEX(tblStellplatz[SAP],MATCH(PlanLayout!I7,tblStellplatz[Stellplatz],0)),5),RIGHT(INDEX(tblStellplatz[SAP],MATCH(PlanLayout!I7,tblStellplatz[Stellplatz],0)),4))),"?")) | ... AO7: =IF(PlanLayout!AO7="","",PlanLayout!AO7&CHAR(10)&IFERROR(IF(INDEX(tblStellplatz[SAP],MATCH(PlanLayout!AO7,tblStellplatz[Stellplatz],0))="","leer",IF(LEFT(RIGHT(INDEX(tblStellplatz[SAP],MATCH(PlanLayout!AO7,tblStellplatz[Stellplatz],0)),4),1)="0",RIGHT(INDEX(tblStellplatz[SAP],MATCH(PlanLayout!AO7,tblStellplatz[Stellplatz],0)),5),RIGHT(INDEX(tblStellplatz[SAP],MATCH(PlanLayout!AO7,tblStellplatz[Stellplatz],0)),4))),"?"))
B8: =IF(PlanLayout!B8="","",PlanLayout!B8&CHAR(10)&IFERROR(IF(INDEX(tblStellplatz[SAP],MATCH(PlanLayout!B8,tblStellplatz[Stellplatz],0))="","leer",IF(LEFT(RIGHT(INDEX(tblStellplatz[SAP],MATCH(PlanLayout!B8,tblStellplatz[Stellplatz],0)),4),1)="0",RIGHT(INDEX(tblStellplatz[SAP],MATCH(PlanLayout!B8,tblStellplatz[Stellplatz],0)),5),RIGHT(INDEX(tblStellplatz[SAP],MATCH(PlanLayout!B8,tblStellplatz[Stellplatz],0)),4))),"?")) | C8: =IF(PlanLayout!C8="","",PlanLayout!C8&CHAR(10)&IFERROR(IF(INDEX(tblStellplatz[SAP],MATCH(PlanLayout!C8,tblStellplatz[Stellplatz],0))="","leer",IF(LEFT(RIGHT(INDEX(tblStellplatz[SAP],MATCH(PlanLayout!C8,tblStellplatz[Stellplatz],0)),4),1)="0",RIGHT(INDEX(tblStellplatz[SAP],MATCH(PlanLayout!C8,tblStellplatz[Stellplatz],0)),5),RIGHT(INDEX(tblStellplatz[SAP],MATCH(PlanLayout!C8,tblStellplatz[Stellplatz],0)),4))),"?")) | D8: =IF(PlanLayout!D8="","",PlanLayout!D8&CHAR(10)&IFERROR(IF(INDEX(tblStellplatz[SAP],MATCH(PlanLayout!D8,tblStellplatz[Stellplatz],0))="","leer",IF(LEFT(RIGHT(INDEX(tblStellplatz[SAP],MATCH(PlanLayout!D8,tblStellplatz[Stellplatz],0)),4),1)="0",RIGHT(INDEX(tblStellplatz[SAP],MATCH(PlanLayout!D8,tblStellplatz[Stellplatz],0)),5),RIGHT(INDEX(tblStellplatz[SAP],MATCH(PlanLayout!D8,tblStellplatz[Stellplatz],0)),4))),"?")) | E8: =IF(PlanLayout!E8="","",PlanLayout!E8&CHAR(10)&IFERROR(IF(INDEX(tblStellplatz[SAP],MATCH(PlanLayout!E8,tblStellplatz[Stellplatz],0))="","leer",IF(LEFT(RIGHT(INDEX(tblStellplatz[SAP],MATCH(PlanLayout!E8,tblStellplatz[Stellplatz],0)),4),1)="0",RIGHT(INDEX(tblStellplatz[SAP],MATCH(PlanLayout!E8,tblStellplatz[Stellplatz],0)),5),RIGHT(INDEX(tblStellplatz[SAP],MATCH(PlanLayout!E8,tblStellplatz[Stellplatz],0)),4))),"?")) | F8: =IF(PlanLayout!F8="","",PlanLayout!F8&CHAR(10)&IFERROR(IF(INDEX(tblStellplatz[SAP],MATCH(PlanLayout!F8,tblStellplatz[Stellplatz],0))="","leer",IF(LEFT(RIGHT(INDEX(tblStellplatz[SAP],MATCH(PlanLayout!F8,tblStellplatz[Stellplatz],0)),4),1)="0",RIGHT(INDEX(tblStellplatz[SAP],MATCH(PlanLayout!F8,tblStellplatz[Stellplatz],0)),5),RIGHT(INDEX(tblStellplatz[SAP],MATCH(PlanLayout!F8,tblStellplatz[Stellplatz],0)),4))),"?")) | G8: =IF(PlanLayout!G8="","",PlanLayout!G8&CHAR(10)&IFERROR(IF(INDEX(tblStellplatz[SAP],MATCH(PlanLayout!G8,tblStellplatz[Stellplatz],0))="","leer",IF(LEFT(RIGHT(INDEX(tblStellplatz[SAP],MATCH(PlanLayout!G8,tblStellplatz[Stellplatz],0)),4),1)="0",RIGHT(INDEX(tblStellplatz[SAP],MATCH(PlanLayout!G8,tblStellplatz[Stellplatz],0)),5),RIGHT(INDEX(tblStellplatz[SAP],MATCH(PlanLayout!G8,tblStellplatz[Stellplatz],0)),4))),"?")) | H8: =IF(PlanLayout!H8="","",PlanLayout!H8&CHAR(10)&IFERROR(IF(INDEX(tblStellplatz[SAP],MATCH(PlanLayout!H8,tblStellplatz[Stellplatz],0))="","leer",IF(LEFT(RIGHT(INDEX(tblStellplatz[SAP],MATCH(PlanLayout!H8,tblStellplatz[Stellplatz],0)),4),1)="0",RIGHT(INDEX(tblStellplatz[SAP],MATCH(PlanLayout!H8,tblStellplatz[Stellplatz],0)),5),RIGHT(INDEX(tblStellplatz[SAP],MATCH(PlanLayout!H8,tblStellplatz[Stellplatz],0)),4))),"?")) | I8: =IF(PlanLayout!I8="","",PlanLayout!I8&CHAR(10)&IFERROR(IF(INDEX(tblStellplatz[SAP],MATCH(PlanLayout!I8,tblStellplatz[Stellplatz],0))="","leer",IF(LEFT(RIGHT(INDEX(tblStellplatz[SAP],MATCH(PlanLayout!I8,tblStellplatz[Stellplatz],0)),4),1)="0",RIGHT(INDEX(tblStellplatz[SAP],MATCH(PlanLayout!I8,tblStellplatz[Stellplatz],0)),5),RIGHT(INDEX(tblStellplatz[SAP],MATCH(PlanLayout!I8,tblStellplatz[Stellplatz],0)),4))),"?")) | ... AO8: =IF(PlanLayout!AO8="","",PlanLayout!AO8&CHAR(10)&IFERROR(IF(INDEX(tblStellplatz[SAP],MATCH(PlanLayout!AO8,tblStellplatz[Stellplatz],0))="","leer",IF(LEFT(RIGHT(INDEX(tblStellplatz[SAP],MATCH(PlanLayout!AO8,tblStellplatz[Stellplatz],0)),4),1)="0",RIGHT(INDEX(tblStellplatz[SAP],MATCH(PlanLayout!AO8,tblStellplatz[Stellplatz],0)),5),RIGHT(INDEX(tblStellplatz[SAP],MATCH(PlanLayout!AO8,tblStellplatz[Stellplatz],0)),4))),"?"))
B9: =IF(PlanLayout!B9="","",PlanLayout!B9&CHAR(10)&IFERROR(IF(INDEX(tblStellplatz[SAP],MATCH(PlanLayout!B9,tblStellplatz[Stellplatz],0))="","leer",IF(LEFT(RIGHT(INDEX(tblStellplatz[SAP],MATCH(PlanLayout!B9,tblStellplatz[Stellplatz],0)),4),1)="0",RIGHT(INDEX(tblStellplatz[SAP],MATCH(PlanLayout!B9,tblStellplatz[Stellplatz],0)),5),RIGHT(INDEX(tblStellplatz[SAP],MATCH(PlanLayout!B9,tblStellplatz[Stellplatz],0)),4))),"?")) | C9: =IF(PlanLayout!C9="","",PlanLayout!C9&CHAR(10)&IFERROR(IF(INDEX(tblStellplatz[SAP],MATCH(PlanLayout!C9,tblStellplatz[Stellplatz],0))="","leer",IF(LEFT(RIGHT(INDEX(tblStellplatz[SAP],MATCH(PlanLayout!C9,tblStellplatz[Stellplatz],0)),4),1)="0",RIGHT(INDEX(tblStellplatz[SAP],MATCH(PlanLayout!C9,tblStellplatz[Stellplatz],0)),5),RIGHT(INDEX(tblStellplatz[SAP],MATCH(PlanLayout!C9,tblStellplatz[Stellplatz],0)),4))),"?")) | D9: =IF(PlanLayout!D9="","",PlanLayout!D9&CHAR(10)&IFERROR(IF(INDEX(tblStellplatz[SAP],MATCH(PlanLayout!D9,tblStellplatz[Stellplatz],0))="","leer",IF(LEFT(RIGHT(INDEX(tblStellplatz[SAP],MATCH(PlanLayout!D9,tblStellplatz[Stellplatz],0)),4),1)="0",RIGHT(INDEX(tblStellplatz[SAP],MATCH(PlanLayout!D9,tblStellplatz[Stellplatz],0)),5),RIGHT(INDEX(tblStellplatz[SAP],MATCH(PlanLayout!D9,tblStellplatz[Stellplatz],0)),4))),"?")) | E9: =IF(PlanLayout!E9="","",PlanLayout!E9&CHAR(10)&IFERROR(IF(INDEX(tblStellplatz[SAP],MATCH(PlanLayout!E9,tblStellplatz[Stellplatz],0))="","leer",IF(LEFT(RIGHT(INDEX(tblStellplatz[SAP],MATCH(PlanLayout!E9,tblStellplatz[Stellplatz],0)),4),1)="0",RIGHT(INDEX(tblStellplatz[SAP],MATCH(PlanLayout!E9,tblStellplatz[Stellplatz],0)),5),RIGHT(INDEX(tblStellplatz[SAP],MATCH(PlanLayout!E9,tblStellplatz[Stellplatz],0)),4))),"?")) | F9: =IF(PlanLayout!F9="","",PlanLayout!F9&CHAR(10)&IFERROR(IF(INDEX(tblStellplatz[SAP],MATCH(PlanLayout!F9,tblStellplatz[Stellplatz],0))="","leer",IF(LEFT(RIGHT(INDEX(tblStellplatz[SAP],MATCH(PlanLayout!F9,tblStellplatz[Stellplatz],0)),4),1)="0",RIGHT(INDEX(tblStellplatz[SAP],MATCH(PlanLayout!F9,tblStellplatz[Stellplatz],0)),5),RIGHT(INDEX(tblStellplatz[SAP],MATCH(PlanLayout!F9,tblStellplatz[Stellplatz],0)),4))),"?")) | G9: =IF(PlanLayout!G9="","",PlanLayout!G9&CHAR(10)&IFERROR(IF(INDEX(tblStellplatz[SAP],MATCH(PlanLayout!G9,tblStellplatz[Stellplatz],0))="","leer",IF(LEFT(RIGHT(INDEX(tblStellplatz[SAP],MATCH(PlanLayout!G9,tblStellplatz[Stellplatz],0)),4),1)="0",RIGHT(INDEX(tblStellplatz[SAP],MATCH(PlanLayout!G9,tblStellplatz[Stellplatz],0)),5),RIGHT(INDEX(tblStellplatz[SAP],MATCH(PlanLayout!G9,tblStellplatz[Stellplatz],0)),4))),"?")) | H9: =IF(PlanLayout!H9="","",PlanLayout!H9&CHAR(10)&IFERROR(IF(INDEX(tblStellplatz[SAP],MATCH(PlanLayout!H9,tblStellplatz[Stellplatz],0))="","leer",IF(LEFT(RIGHT(INDEX(tblStellplatz[SAP],MATCH(PlanLayout!H9,tblStellplatz[Stellplatz],0)),4),1)="0",RIGHT(INDEX(tblStellplatz[SAP],MATCH(PlanLayout!H9,tblStellplatz[Stellplatz],0)),5),RIGHT(INDEX(tblStellplatz[SAP],MATCH(PlanLayout!H9,tblStellplatz[Stellplatz],0)),4))),"?")) | I9: =IF(PlanLayout!I9="","",PlanLayout!I9&CHAR(10)&IFERROR(IF(INDEX(tblStellplatz[SAP],MATCH(PlanLayout!I9,tblStellplatz[Stellplatz],0))="","leer",IF(LEFT(RIGHT(INDEX(tblStellplatz[SAP],MATCH(PlanLayout!I9,tblStellplatz[Stellplatz],0)),4),1)="0",RIGHT(INDEX(tblStellplatz[SAP],MATCH(PlanLayout!I9,tblStellplatz[Stellplatz],0)),5),RIGHT(INDEX(tblStellplatz[SAP],MATCH(PlanLayout!I9,tblStellplatz[Stellplatz],0)),4))),"?")) | ... AO9: =IF(PlanLayout!AO9="","",PlanLayout!AO9&CHAR(10)&IFERROR(IF(INDEX(tblStellplatz[SAP],MATCH(PlanLayout!AO9,tblStellplatz[Stellplatz],0))="","leer",IF(LEFT(RIGHT(INDEX(tblStellplatz[SAP],MATCH(PlanLayout!AO9,tblStellplatz[Stellplatz],0)),4),1)="0",RIGHT(INDEX(tblStellplatz[SAP],MATCH(PlanLayout!AO9,tblStellplatz[Stellplatz],0)),5),RIGHT(INDEX(tblStellplatz[SAP],MATCH(PlanLayout!AO9,tblStellplatz[Stellplatz],0)),4))),"?"))
B10: =IF(PlanLayout!B10="","",PlanLayout!B10&CHAR(10)&IFERROR(IF(INDEX(tblStellplatz[SAP],MATCH(PlanLayout!B10,tblStellplatz[Stellplatz],0))="","leer",IF(LEFT(RIGHT(INDEX(tblStellplatz[SAP],MATCH(PlanLayout!B10,tblStellplatz[Stellplatz],0)),4),1)="0",RIGHT(INDEX(tblStellplatz[SAP],MATCH(PlanLayout!B10,tblStellplatz[Stellplatz],0)),5),RIGHT(INDEX(tblStellplatz[SAP],MATCH(PlanLayout!B10,tblStellplatz[Stellplatz],0)),4))),"?")) | C10: =IF(PlanLayout!C10="","",PlanLayout!C10&CHAR(10)&IFERROR(IF(INDEX(tblStellplatz[SAP],MATCH(PlanLayout!C10,tblStellplatz[Stellplatz],0))="","leer",IF(LEFT(RIGHT(INDEX(tblStellplatz[SAP],MATCH(PlanLayout!C10,tblStellplatz[Stellplatz],0)),4),1)="0",RIGHT(INDEX(tblStellplatz[SAP],MATCH(PlanLayout!C10,tblStellplatz[Stellplatz],0)),5),RIGHT(INDEX(tblStellplatz[SAP],MATCH(PlanLayout!C10,tblStellplatz[Stellplatz],0)),4))),"?")) | D10: =IF(PlanLayout!D10="","",PlanLayout!D10&CHAR(10)&IFERROR(IF(INDEX(tblStellplatz[SAP],MATCH(PlanLayout!D10,tblStellplatz[Stellplatz],0))="","leer",IF(LEFT(RIGHT(INDEX(tblStellplatz[SAP],MATCH(PlanLayout!D10,tblStellplatz[Stellplatz],0)),4),1)="0",RIGHT(INDEX(tblStellplatz[SAP],MATCH(PlanLayout!D10,tblStellplatz[Stellplatz],0)),5),RIGHT(INDEX(tblStellplatz[SAP],MATCH(PlanLayout!D10,tblStellplatz[Stellplatz],0)),4))),"?")) | E10: =IF(PlanLayout!E10="","",PlanLayout!E10&CHAR(10)&IFERROR(IF(INDEX(tblStellplatz[SAP],MATCH(PlanLayout!E10,tblStellplatz[Stellplatz],0))="","leer",IF(LEFT(RIGHT(INDEX(tblStellplatz[SAP],MATCH(PlanLayout!E10,tblStellplatz[Stellplatz],0)),4),1)="0",RIGHT(INDEX(tblStellplatz[SAP],MATCH(PlanLayout!E10,tblStellplatz[Stellplatz],0)),5),RIGHT(INDEX(tblStellplatz[SAP],MATCH(PlanLayout!E10,tblStellplatz[Stellplatz],0)),4))),"?")) | F10: =IF(PlanLayout!F10="","",PlanLayout!F10&CHAR(10)&IFERROR(IF(INDEX(tblStellplatz[SAP],MATCH(PlanLayout!F10,tblStellplatz[Stellplatz],0))="","leer",IF(LEFT(RIGHT(INDEX(tblStellplatz[SAP],MATCH(PlanLayout!F10,tblStellplatz[Stellplatz],0)),4),1)="0",RIGHT(INDEX(tblStellplatz[SAP],MATCH(PlanLayout!F10,tblStellplatz[Stellplatz],0)),5),RIGHT(INDEX(tblStellplatz[SAP],MATCH(PlanLayout!F10,tblStellplatz[Stellplatz],0)),4))),"?")) | G10: =IF(PlanLayout!G10="","",PlanLayout!G10&CHAR(10)&IFERROR(IF(INDEX(tblStellplatz[SAP],MATCH(PlanLayout!G10,tblStellplatz[Stellplatz],0))="","leer",IF(LEFT(RIGHT(INDEX(tblStellplatz[SAP],MATCH(PlanLayout!G10,tblStellplatz[Stellplatz],0)),4),1)="0",RIGHT(INDEX(tblStellplatz[SAP],MATCH(PlanLayout!G10,tblStellplatz[Stellplatz],0)),5),RIGHT(INDEX(tblStellplatz[SAP],MATCH(PlanLayout!G10,tblStellplatz[Stellplatz],0)),4))),"?")) | H10: =IF(PlanLayout!H10="","",PlanLayout!H10&CHAR(10)&IFERROR(IF(INDEX(tblStellplatz[SAP],MATCH(PlanLayout!H10,tblStellplatz[Stellplatz],0))="","leer",IF(LEFT(RIGHT(INDEX(tblStellplatz[SAP],MATCH(PlanLayout!H10,tblStellplatz[Stellplatz],0)),4),1)="0",RIGHT(INDEX(tblStellplatz[SAP],MATCH(PlanLayout!H10,tblStellplatz[Stellplatz],0)),5),RIGHT(INDEX(tblStellplatz[SAP],MATCH(PlanLayout!H10,tblStellplatz[Stellplatz],0)),4))),"?")) | I10: =IF(PlanLayout!I10="","",PlanLayout!I10&CHAR(10)&IFERROR(IF(INDEX(tblStellplatz[SAP],MATCH(PlanLayout!I10,tblStellplatz[Stellplatz],0))="","leer",IF(LEFT(RIGHT(INDEX(tblStellplatz[SAP],MATCH(PlanLayout!I10,tblStellplatz[Stellplatz],0)),4),1)="0",RIGHT(INDEX(tblStellplatz[SAP],MATCH(PlanLayout!I10,tblStellplatz[Stellplatz],0)),5),RIGHT(INDEX(tblStellplatz[SAP],MATCH(PlanLayout!I10,tblStellplatz[Stellplatz],0)),4))),"?")) | ... AO10: =IF(PlanLayout!AO10="","",PlanLayout!AO10&CHAR(10)&IFERROR(IF(INDEX(tblStellplatz[SAP],MATCH(PlanLayout!AO10,tblStellplatz[Stellplatz],0))="","leer",IF(LEFT(RIGHT(INDEX(tblStellplatz[SAP],MATCH(PlanLayout!AO10,tblStellplatz[Stellplatz],0)),4),1)="0",RIGHT(INDEX(tblStellplatz[SAP],MATCH(PlanLayout!AO10,tblStellplatz[Stellplatz],0)),5),RIGHT(INDEX(tblStellplatz[SAP],MATCH(PlanLayout!AO10,tblStellplatz[Stellplatz],0)),4))),"?"))
B11: =IF(PlanLayout!B11="","",PlanLayout!B11&CHAR(10)&IFERROR(IF(INDEX(tblStellplatz[SAP],MATCH(PlanLayout!B11,tblStellplatz[Stellplatz],0))="","leer",IF(LEFT(RIGHT(INDEX(tblStellplatz[SAP],MATCH(PlanLayout!B11,tblStellplatz[Stellplatz],0)),4),1)="0",RIGHT(INDEX(tblStellplatz[SAP],MATCH(PlanLayout!B11,tblStellplatz[Stellplatz],0)),5),RIGHT(INDEX(tblStellplatz[SAP],MATCH(PlanLayout!B11,tblStellplatz[Stellplatz],0)),4))),"?")) | C11: =IF(PlanLayout!C11="","",PlanLayout!C11&CHAR(10)&IFERROR(IF(INDEX(tblStellplatz[SAP],MATCH(PlanLayout!C11,tblStellplatz[Stellplatz],0))="","leer",IF(LEFT(RIGHT(INDEX(tblStellplatz[SAP],MATCH(PlanLayout!C11,tblStellplatz[Stellplatz],0)),4),1)="0",RIGHT(INDEX(tblStellplatz[SAP],MATCH(PlanLayout!C11,tblStellplatz[Stellplatz],0)),5),RIGHT(INDEX(tblStellplatz[SAP],MATCH(PlanLayout!C11,tblStellplatz[Stellplatz],0)),4))),"?")) | D11: =IF(PlanLayout!D11="","",PlanLayout!D11&CHAR(10)&IFERROR(IF(INDEX(tblStellplatz[SAP],MATCH(PlanLayout!D11,tblStellplatz[Stellplatz],0))="","leer",IF(LEFT(RIGHT(INDEX(tblStellplatz[SAP],MATCH(PlanLayout!D11,tblStellplatz[Stellplatz],0)),4),1)="0",RIGHT(INDEX(tblStellplatz[SAP],MATCH(PlanLayout!D11,tblStellplatz[Stellplatz],0)),5),RIGHT(INDEX(tblStellplatz[SAP],MATCH(PlanLayout!D11,tblStellplatz[Stellplatz],0)),4))),"?")) | E11: =IF(PlanLayout!E11="","",PlanLayout!E11&CHAR(10)&IFERROR(IF(INDEX(tblStellplatz[SAP],MATCH(PlanLayout!E11,tblStellplatz[Stellplatz],0))="","leer",IF(LEFT(RIGHT(INDEX(tblStellplatz[SAP],MATCH(PlanLayout!E11,tblStellplatz[Stellplatz],0)),4),1)="0",RIGHT(INDEX(tblStellplatz[SAP],MATCH(PlanLayout!E11,tblStellplatz[Stellplatz],0)),5),RIGHT(INDEX(tblStellplatz[SAP],MATCH(PlanLayout!E11,tblStellplatz[Stellplatz],0)),4))),"?")) | F11: =IF(PlanLayout!F11="","",PlanLayout!F11&CHAR(10)&IFERROR(IF(INDEX(tblStellplatz[SAP],MATCH(PlanLayout!F11,tblStellplatz[Stellplatz],0))="","leer",IF(LEFT(RIGHT(INDEX(tblStellplatz[SAP],MATCH(PlanLayout!F11,tblStellplatz[Stellplatz],0)),4),1)="0",RIGHT(INDEX(tblStellplatz[SAP],MATCH(PlanLayout!F11,tblStellplatz[Stellplatz],0)),5),RIGHT(INDEX(tblStellplatz[SAP],MATCH(PlanLayout!F11,tblStellplatz[Stellplatz],0)),4))),"?")) | G11: =IF(PlanLayout!G11="","",PlanLayout!G11&CHAR(10)&IFERROR(IF(INDEX(tblStellplatz[SAP],MATCH(PlanLayout!G11,tblStellplatz[Stellplatz],0))="","leer",IF(LEFT(RIGHT(INDEX(tblStellplatz[SAP],MATCH(PlanLayout!G11,tblStellplatz[Stellplatz],0)),4),1)="0",RIGHT(INDEX(tblStellplatz[SAP],MATCH(PlanLayout!G11,tblStellplatz[Stellplatz],0)),5),RIGHT(INDEX(tblStellplatz[SAP],MATCH(PlanLayout!G11,tblStellplatz[Stellplatz],0)),4))),"?")) | H11: =IF(PlanLayout!H11="","",PlanLayout!H11&CHAR(10)&IFERROR(IF(INDEX(tblStellplatz[SAP],MATCH(PlanLayout!H11,tblStellplatz[Stellplatz],0))="","leer",IF(LEFT(RIGHT(INDEX(tblStellplatz[SAP],MATCH(PlanLayout!H11,tblStellplatz[Stellplatz],0)),4),1)="0",RIGHT(INDEX(tblStellplatz[SAP],MATCH(PlanLayout!H11,tblStellplatz[Stellplatz],0)),5),RIGHT(INDEX(tblStellplatz[SAP],MATCH(PlanLayout!H11,tblStellplatz[Stellplatz],0)),4))),"?")) | I11: =IF(PlanLayout!I11="","",PlanLayout!I11&CHAR(10)&IFERROR(IF(INDEX(tblStellplatz[SAP],MATCH(PlanLayout!I11,tblStellplatz[Stellplatz],0))="","leer",IF(LEFT(RIGHT(INDEX(tblStellplatz[SAP],MATCH(PlanLayout!I11,tblStellplatz[Stellplatz],0)),4),1)="0",RIGHT(INDEX(tblStellplatz[SAP],MATCH(PlanLayout!I11,tblStellplatz[Stellplatz],0)),5),RIGHT(INDEX(tblStellplatz[SAP],MATCH(PlanLayout!I11,tblStellplatz[Stellplatz],0)),4))),"?")) | ... AO11: =IF(PlanLayout!AO11="","",PlanLayout!AO11&CHAR(10)&IFERROR(IF(INDEX(tblStellplatz[SAP],MATCH(PlanLayout!AO11,tblStellplatz[Stellplatz],0))="","leer",IF(LEFT(RIGHT(INDEX(tblStellplatz[SAP],MATCH(PlanLayout!AO11,tblStellplatz[Stellplatz],0)),4),1)="0",RIGHT(INDEX(tblStellplatz[SAP],MATCH(PlanLayout!AO11,tblStellplatz[Stellplatz],0)),5),RIGHT(INDEX(tblStellplatz[SAP],MATCH(PlanLayout!AO11,tblStellplatz[Stellplatz],0)),4))),"?"))
B12: =IF(PlanLayout!B12="","",PlanLayout!B12&CHAR(10)&IFERROR(IF(INDEX(tblStellplatz[SAP],MATCH(PlanLayout!B12,tblStellplatz[Stellplatz],0))="","leer",IF(LEFT(RIGHT(INDEX(tblStellplatz[SAP],MATCH(PlanLayout!B12,tblStellplatz[Stellplatz],0)),4),1)="0",RIGHT(INDEX(tblStellplatz[SAP],MATCH(PlanLayout!B12,tblStellplatz[Stellplatz],0)),5),RIGHT(INDEX(tblStellplatz[SAP],MATCH(PlanLayout!B12,tblStellplatz[Stellplatz],0)),4))),"?")) | C12: =IF(PlanLayout!C12="","",PlanLayout!C12&CHAR(10)&IFERROR(IF(INDEX(tblStellplatz[SAP],MATCH(PlanLayout!C12,tblStellplatz[Stellplatz],0))="","leer",IF(LEFT(RIGHT(INDEX(tblStellplatz[SAP],MATCH(PlanLayout!C12,tblStellplatz[Stellplatz],0)),4),1)="0",RIGHT(INDEX(tblStellplatz[SAP],MATCH(PlanLayout!C12,tblStellplatz[Stellplatz],0)),5),RIGHT(INDEX(tblStellplatz[SAP],MATCH(PlanLayout!C12,tblStellplatz[Stellplatz],0)),4))),"?")) | D12: =IF(PlanLayout!D12="","",PlanLayout!D12&CHAR(10)&IFERROR(IF(INDEX(tblStellplatz[SAP],MATCH(PlanLayout!D12,tblStellplatz[Stellplatz],0))="","leer",IF(LEFT(RIGHT(INDEX(tblStellplatz[SAP],MATCH(PlanLayout!D12,tblStellplatz[Stellplatz],0)),4),1)="0",RIGHT(INDEX(tblStellplatz[SAP],MATCH(PlanLayout!D12,tblStellplatz[Stellplatz],0)),5),RIGHT(INDEX(tblStellplatz[SAP],MATCH(PlanLayout!D12,tblStellplatz[Stellplatz],0)),4))),"?")) | E12: =IF(PlanLayout!E12="","",PlanLayout!E12&CHAR(10)&IFERROR(IF(INDEX(tblStellplatz[SAP],MATCH(PlanLayout!E12,tblStellplatz[Stellplatz],0))="","leer",IF(LEFT(RIGHT(INDEX(tblStellplatz[SAP],MATCH(PlanLayout!E12,tblStellplatz[Stellplatz],0)),4),1)="0",RIGHT(INDEX(tblStellplatz[SAP],MATCH(PlanLayout!E12,tblStellplatz[Stellplatz],0)),5),RIGHT(INDEX(tblStellplatz[SAP],MATCH(PlanLayout!E12,tblStellplatz[Stellplatz],0)),4))),"?")) | F12: =IF(PlanLayout!F12="","",PlanLayout!F12&CHAR(10)&IFERROR(IF(INDEX(tblStellplatz[SAP],MATCH(PlanLayout!F12,tblStellplatz[Stellplatz],0))="","leer",IF(LEFT(RIGHT(INDEX(tblStellplatz[SAP],MATCH(PlanLayout!F12,tblStellplatz[Stellplatz],0)),4),1)="0",RIGHT(INDEX(tblStellplatz[SAP],MATCH(PlanLayout!F12,tblStellplatz[Stellplatz],0)),5),RIGHT(INDEX(tblStellplatz[SAP],MATCH(PlanLayout!F12,tblStellplatz[Stellplatz],0)),4))),"?")) | G12: =IF(PlanLayout!G12="","",PlanLayout!G12&CHAR(10)&IFERROR(IF(INDEX(tblStellplatz[SAP],MATCH(PlanLayout!G12,tblStellplatz[Stellplatz],0))="","leer",IF(LEFT(RIGHT(INDEX(tblStellplatz[SAP],MATCH(PlanLayout!G12,tblStellplatz[Stellplatz],0)),4),1)="0",RIGHT(INDEX(tblStellplatz[SAP],MATCH(PlanLayout!G12,tblStellplatz[Stellplatz],0)),5),RIGHT(INDEX(tblStellplatz[SAP],MATCH(PlanLayout!G12,tblStellplatz[Stellplatz],0)),4))),"?")) | H12: =IF(PlanLayout!H12="","",PlanLayout!H12&CHAR(10)&IFERROR(IF(INDEX(tblStellplatz[SAP],MATCH(PlanLayout!H12,tblStellplatz[Stellplatz],0))="","leer",IF(LEFT(RIGHT(INDEX(tblStellplatz[SAP],MATCH(PlanLayout!H12,tblStellplatz[Stellplatz],0)),4),1)="0",RIGHT(INDEX(tblStellplatz[SAP],MATCH(PlanLayout!H12,tblStellplatz[Stellplatz],0)),5),RIGHT(INDEX(tblStellplatz[SAP],MATCH(PlanLayout!H12,tblStellplatz[Stellplatz],0)),4))),"?")) | I12: =IF(PlanLayout!I12="","",PlanLayout!I12&CHAR(10)&IFERROR(IF(INDEX(tblStellplatz[SAP],MATCH(PlanLayout!I12,tblStellplatz[Stellplatz],0))="","leer",IF(LEFT(RIGHT(INDEX(tblStellplatz[SAP],MATCH(PlanLayout!I12,tblStellplatz[Stellplatz],0)),4),1)="0",RIGHT(INDEX(tblStellplatz[SAP],MATCH(PlanLayout!I12,tblStellplatz[Stellplatz],0)),5),RIGHT(INDEX(tblStellplatz[SAP],MATCH(PlanLayout!I12,tblStellplatz[Stellplatz],0)),4))),"?")) | ... AO12: =IF(PlanLayout!AO12="","",PlanLayout!AO12&CHAR(10)&IFERROR(IF(INDEX(tblStellplatz[SAP],MATCH(PlanLayout!AO12,tblStellplatz[Stellplatz],0))="","leer",IF(LEFT(RIGHT(INDEX(tblStellplatz[SAP],MATCH(PlanLayout!AO12,tblStellplatz[Stellplatz],0)),4),1)="0",RIGHT(INDEX(tblStellplatz[SAP],MATCH(PlanLayout!AO12,tblStellplatz[Stellplatz],0)),5),RIGHT(INDEX(tblStellplatz[SAP],MATCH(PlanLayout!AO12,tblStellplatz[Stellplatz],0)),4))),"?"))
B13: =IF(PlanLayout!B13="","",PlanLayout!B13&CHAR(10)&IFERROR(IF(INDEX(tblStellplatz[SAP],MATCH(PlanLayout!B13,tblStellplatz[Stellplatz],0))="","leer",IF(LEFT(RIGHT(INDEX(tblStellplatz[SAP],MATCH(PlanLayout!B13,tblStellplatz[Stellplatz],0)),4),1)="0",RIGHT(INDEX(tblStellplatz[SAP],MATCH(PlanLayout!B13,tblStellplatz[Stellplatz],0)),5),RIGHT(INDEX(tblStellplatz[SAP],MATCH(PlanLayout!B13,tblStellplatz[Stellplatz],0)),4))),"?")) | C13: =IF(PlanLayout!C13="","",PlanLayout!C13&CHAR(10)&IFERROR(IF(INDEX(tblStellplatz[SAP],MATCH(PlanLayout!C13,tblStellplatz[Stellplatz],0))="","leer",IF(LEFT(RIGHT(INDEX(tblStellplatz[SAP],MATCH(PlanLayout!C13,tblStellplatz[Stellplatz],0)),4),1)="0",RIGHT(INDEX(tblStellplatz[SAP],MATCH(PlanLayout!C13,tblStellplatz[Stellplatz],0)),5),RIGHT(INDEX(tblStellplatz[SAP],MATCH(PlanLayout!C13,tblStellplatz[Stellplatz],0)),4))),"?")) | D13: =IF(PlanLayout!D13="","",PlanLayout!D13&CHAR(10)&IFERROR(IF(INDEX(tblStellplatz[SAP],MATCH(PlanLayout!D13,tblStellplatz[Stellplatz],0))="","leer",IF(LEFT(RIGHT(INDEX(tblStellplatz[SAP],MATCH(PlanLayout!D13,tblStellplatz[Stellplatz],0)),4),1)="0",RIGHT(INDEX(tblStellplatz[SAP],MATCH(PlanLayout!D13,tblStellplatz[Stellplatz],0)),5),RIGHT(INDEX(tblStellplatz[SAP],MATCH(PlanLayout!D13,tblStellplatz[Stellplatz],0)),4))),"?")) | E13: =IF(PlanLayout!E13="","",PlanLayout!E13&CHAR(10)&IFERROR(IF(INDEX(tblStellplatz[SAP],MATCH(PlanLayout!E13,tblStellplatz[Stellplatz],0))="","leer",IF(LEFT(RIGHT(INDEX(tblStellplatz[SAP],MATCH(PlanLayout!E13,tblStellplatz[Stellplatz],0)),4),1)="0",RIGHT(INDEX(tblStellplatz[SAP],MATCH(PlanLayout!E13,tblStellplatz[Stellplatz],0)),5),RIGHT(INDEX(tblStellplatz[SAP],MATCH(PlanLayout!E13,tblStellplatz[Stellplatz],0)),4))),"?")) | F13: =IF(PlanLayout!F13="","",PlanLayout!F13&CHAR(10)&IFERROR(IF(INDEX(tblStellplatz[SAP],MATCH(PlanLayout!F13,tblStellplatz[Stellplatz],0))="","leer",IF(LEFT(RIGHT(INDEX(tblStellplatz[SAP],MATCH(PlanLayout!F13,tblStellplatz[Stellplatz],0)),4),1)="0",RIGHT(INDEX(tblStellplatz[SAP],MATCH(PlanLayout!F13,tblStellplatz[Stellplatz],0)),5),RIGHT(INDEX(tblStellplatz[SAP],MATCH(PlanLayout!F13,tblStellplatz[Stellplatz],0)),4))),"?")) | G13: =IF(PlanLayout!G13="","",PlanLayout!G13&CHAR(10)&IFERROR(IF(INDEX(tblStellplatz[SAP],MATCH(PlanLayout!G13,tblStellplatz[Stellplatz],0))="","leer",IF(LEFT(RIGHT(INDEX(tblStellplatz[SAP],MATCH(PlanLayout!G13,tblStellplatz[Stellplatz],0)),4),1)="0",RIGHT(INDEX(tblStellplatz[SAP],MATCH(PlanLayout!G13,tblStellplatz[Stellplatz],0)),5),RIGHT(INDEX(tblStellplatz[SAP],MATCH(PlanLayout!G13,tblStellplatz[Stellplatz],0)),4))),"?")) | H13: =IF(PlanLayout!H13="","",PlanLayout!H13&CHAR(10)&IFERROR(IF(INDEX(tblStellplatz[SAP],MATCH(PlanLayout!H13,tblStellplatz[Stellplatz],0))="","leer",IF(LEFT(RIGHT(INDEX(tblStellplatz[SAP],MATCH(PlanLayout!H13,tblStellplatz[Stellplatz],0)),4),1)="0",RIGHT(INDEX(tblStellplatz[SAP],MATCH(PlanLayout!H13,tblStellplatz[Stellplatz],0)),5),RIGHT(INDEX(tblStellplatz[SAP],MATCH(PlanLayout!H13,tblStellplatz[Stellplatz],0)),4))),"?")) | I13: =IF(PlanLayout!I13="","",PlanLayout!I13&CHAR(10)&IFERROR(IF(INDEX(tblStellplatz[SAP],MATCH(PlanLayout!I13,tblStellplatz[Stellplatz],0))="","leer",IF(LEFT(RIGHT(INDEX(tblStellplatz[SAP],MATCH(PlanLayout!I13,tblStellplatz[Stellplatz],0)),4),1)="0",RIGHT(INDEX(tblStellplatz[SAP],MATCH(PlanLayout!I13,tblStellplatz[Stellplatz],0)),5),RIGHT(INDEX(tblStellplatz[SAP],MATCH(PlanLayout!I13,tblStellplatz[Stellplatz],0)),4))),"?")) | ... AO13: =IF(PlanLayout!AO13="","",PlanLayout!AO13&CHAR(10)&IFERROR(IF(INDEX(tblStellplatz[SAP],MATCH(PlanLayout!AO13,tblStellplatz[Stellplatz],0))="","leer",IF(LEFT(RIGHT(INDEX(tblStellplatz[SAP],MATCH(PlanLayout!AO13,tblStellplatz[Stellplatz],0)),4),1)="0",RIGHT(INDEX(tblStellplatz[SAP],MATCH(PlanLayout!AO13,tblStellplatz[Stellplatz],0)),5),RIGHT(INDEX(tblStellplatz[SAP],MATCH(PlanLayout!AO13,tblStellplatz[Stellplatz],0)),4))),"?"))
